[2024-01-10T00:50:56.844+0000] {taskinstance.py:1957} INFO - Dependencies all met for dep_context=non-requeueable deps ti=<TaskInstance: data_ingestion_gcs_dag.local_to_gcs_task scheduled__2023-04-17T00:00:00+00:00 [queued]>
[2024-01-10T00:50:56.929+0000] {taskinstance.py:1957} INFO - Dependencies all met for dep_context=requeueable deps ti=<TaskInstance: data_ingestion_gcs_dag.local_to_gcs_task scheduled__2023-04-17T00:00:00+00:00 [queued]>
[2024-01-10T00:50:56.929+0000] {taskinstance.py:2171} INFO - Starting attempt 1 of 1
[2024-01-10T00:50:57.154+0000] {taskinstance.py:2192} INFO - Executing <Task(PythonOperator): local_to_gcs_task> on 2023-04-17 00:00:00+00:00
[2024-01-10T00:50:57.232+0000] {standard_task_runner.py:60} INFO - Started process 1704 to run task
[2024-01-10T00:50:57.284+0000] {standard_task_runner.py:87} INFO - Running: ['***', 'tasks', 'run', 'data_ingestion_gcs_dag', 'local_to_gcs_task', 'scheduled__2023-04-17T00:00:00+00:00', '--job-id', '485', '--raw', '--subdir', 'DAGS_FOLDER/data_ingestion_gcp.py', '--cfg-path', '/tmp/tmp6td_31ww']
[2024-01-10T00:50:57.323+0000] {standard_task_runner.py:88} INFO - Job 485: Subtask local_to_gcs_task
[2024-01-10T00:50:57.627+0000] {task_command.py:423} INFO - Running <TaskInstance: data_ingestion_gcs_dag.local_to_gcs_task scheduled__2023-04-17T00:00:00+00:00 [running]> on host 35cf15b90cf8
[2024-01-10T00:50:57.919+0000] {warnings.py:109} WARNING - /home/***/.local/lib/python3.8/site-packages/***/utils/context.py:207: AirflowContextDeprecationWarning: Accessing 'execution_date' from the template is deprecated and will be removed in a future version. Please use 'data_interval_start' or 'logical_date' instead.
  warnings.warn(_create_deprecation_warning(key, self._deprecation_replacements[key]))

[2024-01-10T00:50:58.131+0000] {taskinstance.py:2481} INFO - Exporting env vars: AIRFLOW_CTX_DAG_OWNER='***' AIRFLOW_CTX_DAG_ID='data_ingestion_gcs_dag' AIRFLOW_CTX_TASK_ID='local_to_gcs_task' AIRFLOW_CTX_EXECUTION_DATE='2023-04-17T00:00:00+00:00' AIRFLOW_CTX_TRY_NUMBER='1' AIRFLOW_CTX_DAG_RUN_ID='scheduled__2023-04-17T00:00:00+00:00'
[2024-01-10T00:50:58.806+0000] {ingest_data_gcp_script.py:24} INFO - Starting upload of /opt/***/input_2023-04.parquet to raw/yellow_tripdata_2023_04.parquet
[2024-01-10T00:51:01.447+0000] {taskinstance.py:2699} ERROR - Task failed with exception
Traceback (most recent call last):
  File "/home/airflow/.local/lib/python3.8/site-packages/google/cloud/storage/blob.py", line 2607, in _prep_and_do_upload
    created_json = self._do_upload(
  File "/home/airflow/.local/lib/python3.8/site-packages/google/cloud/storage/blob.py", line 2430, in _do_upload
    response = self._do_resumable_upload(
  File "/home/airflow/.local/lib/python3.8/site-packages/google/cloud/storage/blob.py", line 2266, in _do_resumable_upload
    response = upload.transmit_next_chunk(transport, timeout=timeout)
  File "/home/airflow/.local/lib/python3.8/site-packages/google/resumable_media/requests/upload.py", line 515, in transmit_next_chunk
    return _request_helpers.wait_and_retry(
  File "/home/airflow/.local/lib/python3.8/site-packages/google/resumable_media/requests/_request_helpers.py", line 178, in wait_and_retry
    raise error
  File "/home/airflow/.local/lib/python3.8/site-packages/google/resumable_media/requests/_request_helpers.py", line 155, in wait_and_retry
    response = func()
  File "/home/airflow/.local/lib/python3.8/site-packages/google/resumable_media/requests/upload.py", line 511, in retriable_request
    self._process_resumable_response(result, len(payload))
  File "/home/airflow/.local/lib/python3.8/site-packages/google/resumable_media/_upload.py", line 690, in _process_resumable_response
    status_code = _helpers.require_status_code(
  File "/home/airflow/.local/lib/python3.8/site-packages/google/resumable_media/_helpers.py", line 108, in require_status_code
    raise common.InvalidResponse(
google.resumable_media.common.InvalidResponse: ('Request failed with status code', 429, 'Expected one of', 200, 308)

During handling of the above exception, another exception occurred:

Traceback (most recent call last):
  File "/home/airflow/.local/lib/python3.8/site-packages/airflow/models/taskinstance.py", line 433, in _execute_task
    result = execute_callable(context=context, **execute_callable_kwargs)
  File "/home/airflow/.local/lib/python3.8/site-packages/airflow/operators/python.py", line 199, in execute
    return_value = self.execute_callable()
  File "/home/airflow/.local/lib/python3.8/site-packages/airflow/operators/python.py", line 216, in execute_callable
    return self.python_callable(*self.op_args, **self.op_kwargs)
  File "/opt/airflow/dags/ingest_data_gcp_script.py", line 26, in upload_to_gcs
    blob.upload_from_file(f, rewind=True)
  File "/home/airflow/.local/lib/python3.8/site-packages/google/cloud/storage/blob.py", line 2766, in upload_from_file
    self._prep_and_do_upload(
  File "/home/airflow/.local/lib/python3.8/site-packages/google/cloud/storage/blob.py", line 2625, in _prep_and_do_upload
    _raise_from_invalid_response(exc)
  File "/home/airflow/.local/lib/python3.8/site-packages/google/cloud/storage/blob.py", line 4791, in _raise_from_invalid_response
    raise exceptions.from_http_status(response.status_code, message, response=response)
google.api_core.exceptions.TooManyRequests: 429 PUT https://storage.googleapis.com/upload/storage/v1/b/dtc-de-project1-terra-bucket/o?uploadType=resumable&upload_id=ABPtcPqg9Qc3vPuiN9FdWz5LYFDrOoyRmYxmjDBUhcZhCoWrWug_J-BnJg5OixMSocTgzQhiMsPGKdZLFo8lkK0WIN6LqYL9mLQ-j_ifNWN-jjQ9: {
  "error": {
    "code": 429,
    "message": "The object dtc-de-project1-terra-bucket/raw/yellow_tripdata_2023_04.parquet exceeded the rate limit for object mutation operations (create, update, and delete). Please reduce your request rate. See https://cloud.google.com/storage/docs/gcs429.",
    "errors": [
      {
        "message": "The object dtc-de-project1-terra-bucket/raw/yellow_tripdata_2023_04.parquet exceeded the rate limit for object mutation operations (create, update, and delete). Please reduce your request rate. See https://cloud.google.com/storage/docs/gcs429.",
        "domain": "usageLimits",
        "reason": "rateLimitExceeded"
      }
    ]
  }
}
: ('Request failed with status code', 429, 'Expected one of', <HTTPStatus.OK: 200>, <HTTPStatus.PERMANENT_REDIRECT: 308>)
[2024-01-10T00:51:01.492+0000] {taskinstance.py:1138} INFO - Marking task as FAILED. dag_id=data_ingestion_gcs_dag, task_id=local_to_gcs_task, execution_date=20230417T000000, start_date=20240110T005056, end_date=20240110T005101
[2024-01-10T00:51:01.691+0000] {standard_task_runner.py:107} ERROR - Failed to execute job 485 for task local_to_gcs_task (429 PUT https://storage.googleapis.com/upload/storage/v1/b/dtc-de-project1-terra-bucket/o?uploadType=resumable&upload_id=ABPtcPqg9Qc3vPuiN9FdWz5LYFDrOoyRmYxmjDBUhcZhCoWrWug_J-BnJg5OixMSocTgzQhiMsPGKdZLFo8lkK0WIN6LqYL9mLQ-j_ifNWN-jjQ9: {
  "error": {
    "code": 429,
    "message": "The object dtc-de-project1-terra-bucket/raw/yellow_tripdata_2023_04.parquet exceeded the rate limit for object mutation operations (create, update, and delete). Please reduce your request rate. See https://cloud.google.com/storage/docs/gcs429.",
    "errors": [
      {
        "message": "The object dtc-de-project1-terra-bucket/raw/yellow_tripdata_2023_04.parquet exceeded the rate limit for object mutation operations (create, update, and delete). Please reduce your request rate. See https://cloud.google.com/storage/docs/gcs429.",
        "domain": "usageLimits",
        "reason": "rateLimitExceeded"
      }
    ]
  }
}
: ('Request failed with status code', 429, 'Expected one of', <HTTPStatus.OK: 200>, <HTTPStatus.PERMANENT_REDIRECT: 308>); 1704)
[2024-01-10T00:51:01.781+0000] {local_task_job_runner.py:234} INFO - Task exited with return code 1
[2024-01-10T00:51:01.944+0000] {taskinstance.py:3281} INFO - 0 downstream tasks scheduled from follow-on schedule check
