[2024-01-09T21:12:20.793+0000] {taskinstance.py:1957} INFO - Dependencies all met for dep_context=non-requeueable deps ti=<TaskInstance: data_ingestion_gcs_dag.bigquery_external_table_task scheduled__2023-12-02T07:00:00+00:00 [queued]>
[2024-01-09T21:12:20.807+0000] {taskinstance.py:1957} INFO - Dependencies all met for dep_context=requeueable deps ti=<TaskInstance: data_ingestion_gcs_dag.bigquery_external_table_task scheduled__2023-12-02T07:00:00+00:00 [queued]>
[2024-01-09T21:12:20.808+0000] {taskinstance.py:2171} INFO - Starting attempt 3 of 4
[2024-01-09T21:12:20.824+0000] {taskinstance.py:2192} INFO - Executing <Task(BigQueryCreateExternalTableOperator): bigquery_external_table_task> on 2023-12-02 07:00:00+00:00
[2024-01-09T21:12:20.833+0000] {standard_task_runner.py:60} INFO - Started process 3853 to run task
[2024-01-09T21:12:20.839+0000] {standard_task_runner.py:87} INFO - Running: ['***', 'tasks', 'run', 'data_ingestion_gcs_dag', 'bigquery_external_table_task', 'scheduled__2023-12-02T07:00:00+00:00', '--job-id', '107', '--raw', '--subdir', 'DAGS_FOLDER/data_ingestion_gcp.py', '--cfg-path', '/tmp/tmp0dqv34sp']
[2024-01-09T21:12:20.844+0000] {standard_task_runner.py:88} INFO - Job 107: Subtask bigquery_external_table_task
[2024-01-09T21:12:20.914+0000] {task_command.py:423} INFO - Running <TaskInstance: data_ingestion_gcs_dag.bigquery_external_table_task scheduled__2023-12-02T07:00:00+00:00 [running]> on host f5de67cb9685
[2024-01-09T21:12:20.976+0000] {warnings.py:109} WARNING - /home/***/.local/lib/python3.8/site-packages/***/utils/context.py:207: AirflowContextDeprecationWarning: Accessing 'execution_date' from the template is deprecated and will be removed in a future version. Please use 'data_interval_start' or 'logical_date' instead.
  warnings.warn(_create_deprecation_warning(key, self._deprecation_replacements[key]))

[2024-01-09T21:12:21.021+0000] {taskinstance.py:2481} INFO - Exporting env vars: AIRFLOW_CTX_DAG_OWNER='***' AIRFLOW_CTX_DAG_ID='data_ingestion_gcs_dag' AIRFLOW_CTX_TASK_ID='bigquery_external_table_task' AIRFLOW_CTX_EXECUTION_DATE='2023-12-02T07:00:00+00:00' AIRFLOW_CTX_TRY_NUMBER='3' AIRFLOW_CTX_DAG_RUN_ID='scheduled__2023-12-02T07:00:00+00:00'
[2024-01-09T21:12:21.025+0000] {crypto.py:82} WARNING - empty cryptography key - values will not be stored encrypted.
[2024-01-09T21:12:21.025+0000] {connection.py:234} WARNING - Connection schemes (type: google_cloud_platform) shall not contain '_' according to RFC3986.
[2024-01-09T21:12:21.026+0000] {base.py:83} INFO - Using connection ID 'google_cloud_default' for task execution.
[2024-01-09T21:12:22.871+0000] {taskinstance.py:2699} ERROR - Task failed with exception
Traceback (most recent call last):
  File "/home/airflow/.local/lib/python3.8/site-packages/airflow/models/taskinstance.py", line 433, in _execute_task
    result = execute_callable(context=context, **execute_callable_kwargs)
  File "/home/airflow/.local/lib/python3.8/site-packages/airflow/providers/google/cloud/operators/bigquery.py", line 1781, in execute
    table = bq_hook.create_empty_table(
  File "/home/airflow/.local/lib/python3.8/site-packages/airflow/providers/google/common/hooks/base_google.py", line 475, in inner_wrapper
    return func(self, *args, **kwargs)
  File "/home/airflow/.local/lib/python3.8/site-packages/airflow/providers/google/cloud/hooks/bigquery.py", line 421, in create_empty_table
    return self.get_client(project_id=project_id, location=location).create_table(
  File "/home/airflow/.local/lib/python3.8/site-packages/google/cloud/bigquery/client.py", line 784, in create_table
    api_response = self._call_api(
  File "/home/airflow/.local/lib/python3.8/site-packages/google/cloud/bigquery/client.py", line 818, in _call_api
    return call()
  File "/home/airflow/.local/lib/python3.8/site-packages/google/api_core/retry.py", line 372, in retry_wrapped_func
    return retry_target(
  File "/home/airflow/.local/lib/python3.8/site-packages/google/api_core/retry.py", line 207, in retry_target
    result = target()
  File "/home/airflow/.local/lib/python3.8/site-packages/google/cloud/_http/__init__.py", line 494, in api_request
    raise exceptions.from_http_response(response)
google.api_core.exceptions.BadRequest: 400 POST https://bigquery.googleapis.com/bigquery/v2/projects/dtc-de-project1/datasets/nyc_taxi_raw1/tables?prettyPrint=false: Error while reading table: external_table, error message: Input file is not in Parquet format. File: gs://dtc-de-project1-terra-bucket/raw/yellow_tripdata_2023_12
[2024-01-09T21:12:22.888+0000] {taskinstance.py:1138} INFO - Marking task as UP_FOR_RETRY. dag_id=data_ingestion_gcs_dag, task_id=bigquery_external_table_task, execution_date=20231202T070000, start_date=20240109T211220, end_date=20240109T211222
[2024-01-09T21:12:22.910+0000] {standard_task_runner.py:107} ERROR - Failed to execute job 107 for task bigquery_external_table_task (400 POST https://bigquery.googleapis.com/bigquery/v2/projects/dtc-de-project1/datasets/nyc_taxi_raw1/tables?prettyPrint=false: Error while reading table: external_table, error message: Input file is not in Parquet format. File: gs://dtc-de-project1-terra-bucket/raw/yellow_tripdata_2023_12; 3853)
[2024-01-09T21:12:22.941+0000] {local_task_job_runner.py:234} INFO - Task exited with return code 1
[2024-01-09T21:12:22.968+0000] {taskinstance.py:3281} INFO - 0 downstream tasks scheduled from follow-on schedule check
[2024-01-10T00:25:21.741+0000] {taskinstance.py:1957} INFO - Dependencies all met for dep_context=non-requeueable deps ti=<TaskInstance: data_ingestion_gcs_dag.bigquery_external_table_task scheduled__2023-12-02T07:00:00+00:00 [queued]>
[2024-01-10T00:25:21.768+0000] {taskinstance.py:1957} INFO - Dependencies all met for dep_context=requeueable deps ti=<TaskInstance: data_ingestion_gcs_dag.bigquery_external_table_task scheduled__2023-12-02T07:00:00+00:00 [queued]>
[2024-01-10T00:25:21.768+0000] {taskinstance.py:2171} INFO - Starting attempt 3 of 3
[2024-01-10T00:25:21.791+0000] {taskinstance.py:2192} INFO - Executing <Task(BigQueryCreateExternalTableOperator): bigquery_external_table_task> on 2023-12-02 07:00:00+00:00
[2024-01-10T00:25:21.802+0000] {standard_task_runner.py:60} INFO - Started process 7016 to run task
[2024-01-10T00:25:21.811+0000] {standard_task_runner.py:87} INFO - Running: ['***', 'tasks', 'run', 'data_ingestion_gcs_dag', 'bigquery_external_table_task', 'scheduled__2023-12-02T07:00:00+00:00', '--job-id', '147', '--raw', '--subdir', 'DAGS_FOLDER/data_ingestion_gcp.py', '--cfg-path', '/tmp/tmpc51jepow']
[2024-01-10T00:25:21.818+0000] {standard_task_runner.py:88} INFO - Job 147: Subtask bigquery_external_table_task
[2024-01-10T00:25:21.886+0000] {task_command.py:423} INFO - Running <TaskInstance: data_ingestion_gcs_dag.bigquery_external_table_task scheduled__2023-12-02T07:00:00+00:00 [running]> on host f5de67cb9685
[2024-01-10T00:25:21.946+0000] {warnings.py:109} WARNING - /home/***/.local/lib/python3.8/site-packages/***/utils/context.py:207: AirflowContextDeprecationWarning: Accessing 'execution_date' from the template is deprecated and will be removed in a future version. Please use 'data_interval_start' or 'logical_date' instead.
  warnings.warn(_create_deprecation_warning(key, self._deprecation_replacements[key]))

[2024-01-10T00:25:21.987+0000] {taskinstance.py:2481} INFO - Exporting env vars: AIRFLOW_CTX_DAG_OWNER='***' AIRFLOW_CTX_DAG_ID='data_ingestion_gcs_dag' AIRFLOW_CTX_TASK_ID='bigquery_external_table_task' AIRFLOW_CTX_EXECUTION_DATE='2023-12-02T07:00:00+00:00' AIRFLOW_CTX_TRY_NUMBER='3' AIRFLOW_CTX_DAG_RUN_ID='scheduled__2023-12-02T07:00:00+00:00'
[2024-01-10T00:25:21.990+0000] {crypto.py:82} WARNING - empty cryptography key - values will not be stored encrypted.
[2024-01-10T00:25:21.991+0000] {connection.py:234} WARNING - Connection schemes (type: google_cloud_platform) shall not contain '_' according to RFC3986.
[2024-01-10T00:25:21.992+0000] {base.py:83} INFO - Using connection ID 'google_cloud_default' for task execution.
[2024-01-10T00:25:22.541+0000] {taskinstance.py:2699} ERROR - Task failed with exception
Traceback (most recent call last):
  File "/home/airflow/.local/lib/python3.8/site-packages/airflow/models/taskinstance.py", line 433, in _execute_task
    result = execute_callable(context=context, **execute_callable_kwargs)
  File "/home/airflow/.local/lib/python3.8/site-packages/airflow/providers/google/cloud/operators/bigquery.py", line 1781, in execute
    table = bq_hook.create_empty_table(
  File "/home/airflow/.local/lib/python3.8/site-packages/airflow/providers/google/common/hooks/base_google.py", line 475, in inner_wrapper
    return func(self, *args, **kwargs)
  File "/home/airflow/.local/lib/python3.8/site-packages/airflow/providers/google/cloud/hooks/bigquery.py", line 421, in create_empty_table
    return self.get_client(project_id=project_id, location=location).create_table(
  File "/home/airflow/.local/lib/python3.8/site-packages/google/cloud/bigquery/client.py", line 784, in create_table
    api_response = self._call_api(
  File "/home/airflow/.local/lib/python3.8/site-packages/google/cloud/bigquery/client.py", line 818, in _call_api
    return call()
  File "/home/airflow/.local/lib/python3.8/site-packages/google/api_core/retry.py", line 372, in retry_wrapped_func
    return retry_target(
  File "/home/airflow/.local/lib/python3.8/site-packages/google/api_core/retry.py", line 207, in retry_target
    result = target()
  File "/home/airflow/.local/lib/python3.8/site-packages/google/cloud/_http/__init__.py", line 494, in api_request
    raise exceptions.from_http_response(response)
google.api_core.exceptions.BadRequest: 400 POST https://bigquery.googleapis.com/bigquery/v2/projects/dtc-de-project1/datasets/nyc_taxi_raw1/tables?prettyPrint=false: Error while reading table: external_table, error message: Input file is not in Parquet format. File: gs://dtc-de-project1-terra-bucket/raw/yellow_tripdata_2023_12.parquet
[2024-01-10T00:25:22.558+0000] {taskinstance.py:1138} INFO - Marking task as FAILED. dag_id=data_ingestion_gcs_dag, task_id=bigquery_external_table_task, execution_date=20231202T070000, start_date=20240110T002521, end_date=20240110T002522
[2024-01-10T00:25:22.573+0000] {standard_task_runner.py:107} ERROR - Failed to execute job 147 for task bigquery_external_table_task (400 POST https://bigquery.googleapis.com/bigquery/v2/projects/dtc-de-project1/datasets/nyc_taxi_raw1/tables?prettyPrint=false: Error while reading table: external_table, error message: Input file is not in Parquet format. File: gs://dtc-de-project1-terra-bucket/raw/yellow_tripdata_2023_12.parquet; 7016)
[2024-01-10T00:25:22.589+0000] {local_task_job_runner.py:234} INFO - Task exited with return code 1
[2024-01-10T00:25:22.611+0000] {taskinstance.py:3281} INFO - 0 downstream tasks scheduled from follow-on schedule check
