[2024-01-09T20:54:12.766+0000] {taskinstance.py:1957} INFO - Dependencies all met for dep_context=non-requeueable deps ti=<TaskInstance: data_ingestion_gcs_dag.bigquery_external_table_task scheduled__2023-12-02T07:00:00+00:00 [queued]>
[2024-01-09T20:54:12.777+0000] {taskinstance.py:1957} INFO - Dependencies all met for dep_context=requeueable deps ti=<TaskInstance: data_ingestion_gcs_dag.bigquery_external_table_task scheduled__2023-12-02T07:00:00+00:00 [queued]>
[2024-01-09T20:54:12.778+0000] {taskinstance.py:2171} INFO - Starting attempt 1 of 2
[2024-01-09T20:54:12.795+0000] {taskinstance.py:2192} INFO - Executing <Task(BigQueryCreateExternalTableOperator): bigquery_external_table_task> on 2023-12-02 07:00:00+00:00
[2024-01-09T20:54:12.804+0000] {standard_task_runner.py:60} INFO - Started process 3565 to run task
[2024-01-09T20:54:12.809+0000] {standard_task_runner.py:87} INFO - Running: ['***', 'tasks', 'run', 'data_ingestion_gcs_dag', 'bigquery_external_table_task', 'scheduled__2023-12-02T07:00:00+00:00', '--job-id', '105', '--raw', '--subdir', 'DAGS_FOLDER/data_ingestion_gcp.py', '--cfg-path', '/tmp/tmphm72czz5']
[2024-01-09T20:54:12.814+0000] {standard_task_runner.py:88} INFO - Job 105: Subtask bigquery_external_table_task
[2024-01-09T20:54:12.883+0000] {task_command.py:423} INFO - Running <TaskInstance: data_ingestion_gcs_dag.bigquery_external_table_task scheduled__2023-12-02T07:00:00+00:00 [running]> on host f5de67cb9685
[2024-01-09T20:54:12.942+0000] {warnings.py:109} WARNING - /home/***/.local/lib/python3.8/site-packages/***/utils/context.py:207: AirflowContextDeprecationWarning: Accessing 'execution_date' from the template is deprecated and will be removed in a future version. Please use 'data_interval_start' or 'logical_date' instead.
  warnings.warn(_create_deprecation_warning(key, self._deprecation_replacements[key]))

[2024-01-09T20:54:12.985+0000] {taskinstance.py:2481} INFO - Exporting env vars: AIRFLOW_CTX_DAG_OWNER='***' AIRFLOW_CTX_DAG_ID='data_ingestion_gcs_dag' AIRFLOW_CTX_TASK_ID='bigquery_external_table_task' AIRFLOW_CTX_EXECUTION_DATE='2023-12-02T07:00:00+00:00' AIRFLOW_CTX_TRY_NUMBER='1' AIRFLOW_CTX_DAG_RUN_ID='scheduled__2023-12-02T07:00:00+00:00'
[2024-01-09T20:54:12.989+0000] {crypto.py:82} WARNING - empty cryptography key - values will not be stored encrypted.
[2024-01-09T20:54:12.989+0000] {connection.py:234} WARNING - Connection schemes (type: google_cloud_platform) shall not contain '_' according to RFC3986.
[2024-01-09T20:54:12.990+0000] {base.py:83} INFO - Using connection ID 'google_cloud_default' for task execution.
[2024-01-09T20:54:13.294+0000] {taskinstance.py:2699} ERROR - Task failed with exception
Traceback (most recent call last):
  File "/home/airflow/.local/lib/python3.8/site-packages/airflow/models/taskinstance.py", line 433, in _execute_task
    result = execute_callable(context=context, **execute_callable_kwargs)
  File "/home/airflow/.local/lib/python3.8/site-packages/airflow/providers/google/cloud/operators/bigquery.py", line 1781, in execute
    table = bq_hook.create_empty_table(
  File "/home/airflow/.local/lib/python3.8/site-packages/airflow/providers/google/common/hooks/base_google.py", line 475, in inner_wrapper
    return func(self, *args, **kwargs)
  File "/home/airflow/.local/lib/python3.8/site-packages/airflow/providers/google/cloud/hooks/bigquery.py", line 421, in create_empty_table
    return self.get_client(project_id=project_id, location=location).create_table(
  File "/home/airflow/.local/lib/python3.8/site-packages/google/cloud/bigquery/client.py", line 784, in create_table
    api_response = self._call_api(
  File "/home/airflow/.local/lib/python3.8/site-packages/google/cloud/bigquery/client.py", line 818, in _call_api
    return call()
  File "/home/airflow/.local/lib/python3.8/site-packages/google/api_core/retry.py", line 372, in retry_wrapped_func
    return retry_target(
  File "/home/airflow/.local/lib/python3.8/site-packages/google/api_core/retry.py", line 207, in retry_target
    result = target()
  File "/home/airflow/.local/lib/python3.8/site-packages/google/cloud/_http/__init__.py", line 494, in api_request
    raise exceptions.from_http_response(response)
google.api_core.exceptions.NotFound: 404 POST https://bigquery.googleapis.com/bigquery/v2/projects/dtc-de-project1/datasets/trips_data_all/tables?prettyPrint=false: Not found: Dataset dtc-de-project1:trips_data_all
[2024-01-09T20:54:13.313+0000] {taskinstance.py:1138} INFO - Marking task as UP_FOR_RETRY. dag_id=data_ingestion_gcs_dag, task_id=bigquery_external_table_task, execution_date=20231202T070000, start_date=20240109T205412, end_date=20240109T205413
[2024-01-09T20:54:13.329+0000] {standard_task_runner.py:107} ERROR - Failed to execute job 105 for task bigquery_external_table_task (404 POST https://bigquery.googleapis.com/bigquery/v2/projects/dtc-de-project1/datasets/trips_data_all/tables?prettyPrint=false: Not found: Dataset dtc-de-project1:trips_data_all; 3565)
[2024-01-09T20:54:13.343+0000] {local_task_job_runner.py:234} INFO - Task exited with return code 1
[2024-01-09T20:54:13.366+0000] {taskinstance.py:3281} INFO - 0 downstream tasks scheduled from follow-on schedule check
[2024-01-10T00:13:17.143+0000] {taskinstance.py:1957} INFO - Dependencies all met for dep_context=non-requeueable deps ti=<TaskInstance: data_ingestion_gcs_dag.bigquery_external_table_task scheduled__2023-12-02T07:00:00+00:00 [queued]>
[2024-01-10T00:13:17.172+0000] {taskinstance.py:1957} INFO - Dependencies all met for dep_context=requeueable deps ti=<TaskInstance: data_ingestion_gcs_dag.bigquery_external_table_task scheduled__2023-12-02T07:00:00+00:00 [queued]>
[2024-01-10T00:13:17.172+0000] {taskinstance.py:2171} INFO - Starting attempt 1 of 1
[2024-01-10T00:13:17.190+0000] {taskinstance.py:2192} INFO - Executing <Task(BigQueryCreateExternalTableOperator): bigquery_external_table_task> on 2023-12-02 07:00:00+00:00
[2024-01-10T00:13:17.200+0000] {standard_task_runner.py:60} INFO - Started process 6798 to run task
[2024-01-10T00:13:17.206+0000] {standard_task_runner.py:87} INFO - Running: ['***', 'tasks', 'run', 'data_ingestion_gcs_dag', 'bigquery_external_table_task', 'scheduled__2023-12-02T07:00:00+00:00', '--job-id', '139', '--raw', '--subdir', 'DAGS_FOLDER/data_ingestion_gcp.py', '--cfg-path', '/tmp/tmp_acckt25']
[2024-01-10T00:13:17.213+0000] {standard_task_runner.py:88} INFO - Job 139: Subtask bigquery_external_table_task
[2024-01-10T00:13:17.303+0000] {task_command.py:423} INFO - Running <TaskInstance: data_ingestion_gcs_dag.bigquery_external_table_task scheduled__2023-12-02T07:00:00+00:00 [running]> on host f5de67cb9685
[2024-01-10T00:13:17.386+0000] {warnings.py:109} WARNING - /home/***/.local/lib/python3.8/site-packages/***/utils/context.py:207: AirflowContextDeprecationWarning: Accessing 'execution_date' from the template is deprecated and will be removed in a future version. Please use 'data_interval_start' or 'logical_date' instead.
  warnings.warn(_create_deprecation_warning(key, self._deprecation_replacements[key]))

[2024-01-10T00:13:17.433+0000] {taskinstance.py:2481} INFO - Exporting env vars: AIRFLOW_CTX_DAG_OWNER='***' AIRFLOW_CTX_DAG_ID='data_ingestion_gcs_dag' AIRFLOW_CTX_TASK_ID='bigquery_external_table_task' AIRFLOW_CTX_EXECUTION_DATE='2023-12-02T07:00:00+00:00' AIRFLOW_CTX_TRY_NUMBER='1' AIRFLOW_CTX_DAG_RUN_ID='scheduled__2023-12-02T07:00:00+00:00'
[2024-01-10T00:13:17.436+0000] {crypto.py:82} WARNING - empty cryptography key - values will not be stored encrypted.
[2024-01-10T00:13:17.437+0000] {connection.py:234} WARNING - Connection schemes (type: google_cloud_platform) shall not contain '_' according to RFC3986.
[2024-01-10T00:13:17.438+0000] {base.py:83} INFO - Using connection ID 'google_cloud_default' for task execution.
[2024-01-10T00:13:17.928+0000] {taskinstance.py:2699} ERROR - Task failed with exception
Traceback (most recent call last):
  File "/home/airflow/.local/lib/python3.8/site-packages/airflow/models/taskinstance.py", line 433, in _execute_task
    result = execute_callable(context=context, **execute_callable_kwargs)
  File "/home/airflow/.local/lib/python3.8/site-packages/airflow/providers/google/cloud/operators/bigquery.py", line 1781, in execute
    table = bq_hook.create_empty_table(
  File "/home/airflow/.local/lib/python3.8/site-packages/airflow/providers/google/common/hooks/base_google.py", line 475, in inner_wrapper
    return func(self, *args, **kwargs)
  File "/home/airflow/.local/lib/python3.8/site-packages/airflow/providers/google/cloud/hooks/bigquery.py", line 421, in create_empty_table
    return self.get_client(project_id=project_id, location=location).create_table(
  File "/home/airflow/.local/lib/python3.8/site-packages/google/cloud/bigquery/client.py", line 784, in create_table
    api_response = self._call_api(
  File "/home/airflow/.local/lib/python3.8/site-packages/google/cloud/bigquery/client.py", line 818, in _call_api
    return call()
  File "/home/airflow/.local/lib/python3.8/site-packages/google/api_core/retry.py", line 372, in retry_wrapped_func
    return retry_target(
  File "/home/airflow/.local/lib/python3.8/site-packages/google/api_core/retry.py", line 207, in retry_target
    result = target()
  File "/home/airflow/.local/lib/python3.8/site-packages/google/cloud/_http/__init__.py", line 494, in api_request
    raise exceptions.from_http_response(response)
google.api_core.exceptions.BadRequest: 400 POST https://bigquery.googleapis.com/bigquery/v2/projects/dtc-de-project1/datasets/nyc_taxi_raw1/tables?prettyPrint=false: Error while reading table: external_table, error message: Input file is not in Parquet format. File: gs://dtc-de-project1-terra-bucket/raw/yellow_tripdata_2023_12.parquet
[2024-01-10T00:13:17.958+0000] {taskinstance.py:1138} INFO - Marking task as FAILED. dag_id=data_ingestion_gcs_dag, task_id=bigquery_external_table_task, execution_date=20231202T070000, start_date=20240110T001317, end_date=20240110T001317
[2024-01-10T00:13:17.980+0000] {standard_task_runner.py:107} ERROR - Failed to execute job 139 for task bigquery_external_table_task (400 POST https://bigquery.googleapis.com/bigquery/v2/projects/dtc-de-project1/datasets/nyc_taxi_raw1/tables?prettyPrint=false: Error while reading table: external_table, error message: Input file is not in Parquet format. File: gs://dtc-de-project1-terra-bucket/raw/yellow_tripdata_2023_12.parquet; 6798)
[2024-01-10T00:13:18.020+0000] {local_task_job_runner.py:234} INFO - Task exited with return code 1
[2024-01-10T00:13:18.045+0000] {taskinstance.py:3281} INFO - 0 downstream tasks scheduled from follow-on schedule check
