[2024-01-10T00:32:37.222+0000] {taskinstance.py:1957} INFO - Dependencies all met for dep_context=non-requeueable deps ti=<TaskInstance: data_ingestion_gcs_dag.bigquery_external_table_task manual__2024-01-10T00:32:19.334976+00:00 [queued]>
[2024-01-10T00:32:37.260+0000] {taskinstance.py:1957} INFO - Dependencies all met for dep_context=requeueable deps ti=<TaskInstance: data_ingestion_gcs_dag.bigquery_external_table_task manual__2024-01-10T00:32:19.334976+00:00 [queued]>
[2024-01-10T00:32:37.261+0000] {taskinstance.py:2171} INFO - Starting attempt 1 of 1
[2024-01-10T00:32:37.383+0000] {taskinstance.py:2192} INFO - Executing <Task(BigQueryCreateExternalTableOperator): bigquery_external_table_task> on 2024-01-10 00:32:19.334976+00:00
[2024-01-10T00:32:37.438+0000] {standard_task_runner.py:60} INFO - Started process 98 to run task
[2024-01-10T00:32:37.484+0000] {standard_task_runner.py:87} INFO - Running: ['***', 'tasks', 'run', 'data_ingestion_gcs_dag', 'bigquery_external_table_task', 'manual__2024-01-10T00:32:19.334976+00:00', '--job-id', '161', '--raw', '--subdir', 'DAGS_FOLDER/data_ingestion_gcp.py', '--cfg-path', '/tmp/tmpnvjwoyga']
[2024-01-10T00:32:37.520+0000] {standard_task_runner.py:88} INFO - Job 161: Subtask bigquery_external_table_task
[2024-01-10T00:32:37.932+0000] {task_command.py:423} INFO - Running <TaskInstance: data_ingestion_gcs_dag.bigquery_external_table_task manual__2024-01-10T00:32:19.334976+00:00 [running]> on host 35cf15b90cf8
[2024-01-10T00:32:38.225+0000] {warnings.py:109} WARNING - /home/***/.local/lib/python3.8/site-packages/***/utils/context.py:207: AirflowContextDeprecationWarning: Accessing 'execution_date' from the template is deprecated and will be removed in a future version. Please use 'data_interval_start' or 'logical_date' instead.
  warnings.warn(_create_deprecation_warning(key, self._deprecation_replacements[key]))

[2024-01-10T00:32:38.364+0000] {taskinstance.py:2481} INFO - Exporting env vars: AIRFLOW_CTX_DAG_OWNER='***' AIRFLOW_CTX_DAG_ID='data_ingestion_gcs_dag' AIRFLOW_CTX_TASK_ID='bigquery_external_table_task' AIRFLOW_CTX_EXECUTION_DATE='2024-01-10T00:32:19.334976+00:00' AIRFLOW_CTX_TRY_NUMBER='1' AIRFLOW_CTX_DAG_RUN_ID='manual__2024-01-10T00:32:19.334976+00:00'
[2024-01-10T00:32:38.382+0000] {crypto.py:82} WARNING - empty cryptography key - values will not be stored encrypted.
[2024-01-10T00:32:38.386+0000] {connection.py:234} WARNING - Connection schemes (type: google_cloud_platform) shall not contain '_' according to RFC3986.
[2024-01-10T00:32:38.391+0000] {base.py:83} INFO - Using connection ID 'google_cloud_default' for task execution.
[2024-01-10T00:32:39.863+0000] {taskinstance.py:2699} ERROR - Task failed with exception
Traceback (most recent call last):
  File "/home/airflow/.local/lib/python3.8/site-packages/airflow/models/taskinstance.py", line 433, in _execute_task
    result = execute_callable(context=context, **execute_callable_kwargs)
  File "/home/airflow/.local/lib/python3.8/site-packages/airflow/providers/google/cloud/operators/bigquery.py", line 1781, in execute
    table = bq_hook.create_empty_table(
  File "/home/airflow/.local/lib/python3.8/site-packages/airflow/providers/google/common/hooks/base_google.py", line 475, in inner_wrapper
    return func(self, *args, **kwargs)
  File "/home/airflow/.local/lib/python3.8/site-packages/airflow/providers/google/cloud/hooks/bigquery.py", line 421, in create_empty_table
    return self.get_client(project_id=project_id, location=location).create_table(
  File "/home/airflow/.local/lib/python3.8/site-packages/google/cloud/bigquery/client.py", line 784, in create_table
    api_response = self._call_api(
  File "/home/airflow/.local/lib/python3.8/site-packages/google/cloud/bigquery/client.py", line 818, in _call_api
    return call()
  File "/home/airflow/.local/lib/python3.8/site-packages/google/api_core/retry.py", line 372, in retry_wrapped_func
    return retry_target(
  File "/home/airflow/.local/lib/python3.8/site-packages/google/api_core/retry.py", line 207, in retry_target
    result = target()
  File "/home/airflow/.local/lib/python3.8/site-packages/google/cloud/_http/__init__.py", line 494, in api_request
    raise exceptions.from_http_response(response)
google.api_core.exceptions.BadRequest: 400 POST https://bigquery.googleapis.com/bigquery/v2/projects/dtc-de-project1/datasets/nyc_taxi_raw1/tables?prettyPrint=false: Error while reading table: external_table, error message: Input file is not in Parquet format. File: gs://dtc-de-project1-terra-bucket/raw/yellow_tripdata_2024_01.parquet
[2024-01-10T00:32:39.969+0000] {taskinstance.py:1138} INFO - Marking task as FAILED. dag_id=data_ingestion_gcs_dag, task_id=bigquery_external_table_task, execution_date=20240110T003219, start_date=20240110T003237, end_date=20240110T003239
[2024-01-10T00:32:40.102+0000] {standard_task_runner.py:107} ERROR - Failed to execute job 161 for task bigquery_external_table_task (400 POST https://bigquery.googleapis.com/bigquery/v2/projects/dtc-de-project1/datasets/nyc_taxi_raw1/tables?prettyPrint=false: Error while reading table: external_table, error message: Input file is not in Parquet format. File: gs://dtc-de-project1-terra-bucket/raw/yellow_tripdata_2024_01.parquet; 98)
[2024-01-10T00:32:40.188+0000] {local_task_job_runner.py:234} INFO - Task exited with return code 1
[2024-01-10T00:32:40.327+0000] {taskinstance.py:3281} INFO - 0 downstream tasks scheduled from follow-on schedule check
